Workbook

Sheet NOVEMBER 2025 Bill Summary
A1: WSCC Marthandam - Bill Summary -NOVEMBER 2025
A2: Item | B2: Amount (Rs.)
A3: Total monthly bill amount | B3: ='Bill Calculation NOVEMBER 2025'!G17 -> 1619269.7
A4: Total Penalties applied (20% capping applied) | B4: 0
A5: Final Bill amount | B5: =B3-B4 -> 1619269.7
A6: SGST @9% | B6: =B5*0.09 -> 145734.27
A7: CGST @9% | B7: =B5*0.09 -> 145734.27
A8: Total GST | B8: =B6+B7 -> 291468.55
A9: Grand Total | B9: =B5+B8 -> 1910738.3

Sheet Bill Calculation NOVEMBER 2025
A1: Calculation Summary - NOVEMBER 2025
A2: Item | C2: IVR | D2: Agent Seg 1 | E2: Agent Seg 2 | F2: Agent Seg 3 | G2: Total | H2: Remarks
A3: IBD | B3: Unique Calls (Minutes) A | C3: =Table418[[#Totals],[Unit (Minutes)]] -> 151269.15 | D3: =Table721[[#Totals],[Unit (Minutes)]] -> 407402.01 | E3: =Table923[[#Totals],[Unit (Minutes)]] -> 17893.366 | F3: =Table1427[[#Totals],[Unit (Minutes)]] -> 0 | J3: 71116.35 | K3: =J3-C8 -> 19.849144
B4: Repeat Calls (Minutes) B | C4: =Table519[[#Totals],[Unit (Minutes)]] -> 0 | D4: =Table822[[#Totals],[Unit (Minutes)]] -> 1239.6834 | E4: =Table1024[[#Totals],[Unit (Minutes)]] -> 76.983347 | F4: =Table1528[[#Totals],[Unit (Minutes)]] -> 0 | J4: 1271155.4 | K4: =J4-D8 -> 279.76528
B5: Repeat Non applicable Calls (Minutes) C | C5: =Table620[[#Totals],[Unit (Minutes)]] -> 0 | D5: =Table1125[[#Totals],[Unit (Minutes)]] -> 0 | E5: =Table1326[[#Totals],[Unit (Minutes)]] -> 0 | F5: =Table1629[[#Totals],[Unit (Minutes)]] -> 12898.684 | J5: 55919.355 | K5: =J5-E8 -> 31.568693
B6: Actual Bill (Minutes) D | C6: =C3+C4+C5 -> 151269.15 | D6: =D3+D4+D5 -> 408641.69 | E6: =E3+E4+E5 -> 17970.349 | F6: =F3+F4+F5 -> 12898.684 | H6: D=A+B+C | J6: 40699.171 | K6: =J6-F8 -> 584.26445
B7: Per Minute Charge E | C7: 0.47 | D7: 3.11 | E7: 3.11 | F7: 3.11 | J7: 181294.86 | K7: =J7-G16 -> 0
B8: Actual Bill (Rs) F | C8: =C6*C7 -> 71096.501 | D8: =D6*D7 -> 1270875.7 | E8: =E6*E7 -> 55887.786 | F8: =F6*F7 -> 40114.906 | G8: =SUM(C8:F8) -> 1437974.9 | H8: F=D*E
B9: 15 % of Unique Calls G | C9: =C3*0.15 -> 22690.373 | D9: =D3*0.15 -> 61110.301 | E9: =E3*0.15 -> 2684.0049 | F9: =F3*0.15 -> 0 | H9: G=A*0.15
B10: Whether (B > G) H | C10: =IF(C4>C9,"Yes","No") -> No | D10: =IF(D4>D9,"Yes","No") -> No | E10: =IF(E4>E9,"Yes","No") -> No | F10: =IF(F4>F9,"Yes","No") -> No
B11: Net Connect Minutes after deducting Repeat Calls (Rs) I | C11: =C6 -> 151269.15 | D11: =IF(D10="Yes",(D3*1.15)+D5,D6) -> 408641.69 | E11: =IF(E10="Yes",(E3*1.15)+E5,E6) -> 17970.349 | F11: =IF(F10="Yes",(F3*1.15)+F5,F6) -> 12898.684 | H11: If H is Yes, I=(A*1.15) + C Else I=D
B12: Net Amount after deducting Repeat Calls (Rs) J | C12: =C11*C7 -> 71096.501 | D12: =D11*D7 -> 1270875.7 | E12: =E11*E7 -> 55887.786 | F12: =F11*F7 -> 40114.906 | G12: =SUM(C12:F12) -> 1437974.9 | H12: J=I*E
B13: Repeat Call KPI Deduction(Rs) K | C13: =C8-C12 -> 0 | D13: =D8-D12 -> 0 | E13: =E8-E12 -> 0 | F13: =F8-F12 -> 0 | G13: =SUM(C13:F13) -> 0 | H13: K=F-J
A14: OBD | B14: Connect minutes L | D14: =Table7214[[#Totals],[Unit (Minutes)]] -> 58294.167 | E14: =Table9235[[#Totals],[Unit (Minutes)]] -> 0 | F14: =Table16296[[#Totals],[Unit (Minutes)]] -> 0 | G14: =SUM(D14:F14) -> 58294.167
B15: Per Minute Charge (Rs) M | D15: 3.11 | E15: 3.11 | F15: 3.11 | G15: 3.11
B16: Net Amount (Rs) N | D16: =D14*D15 -> 181294.86 | E16: =E14*E15 -> 0 | F16: =F14*F15 -> 0 | G16: =D16+E16+F16 -> 181294.86 | H16: N=L*M
A17: Total Bill amount (Rs) O | G17: =G12+G16 -> 1619269.7 | H17: O=J+N
A18: Call Centre System Uptime SLA (5.1.1) | C18: System Uptime (should be > 99.7%) | G18: 1 | H18: >=99.7% :0%, 98.7to<99.7 :1%, 97to<98.7% :3%, 95to<97% :5%, 90to<95% :10%, <90 :15%
C19: Penalty (Rs) P | G19: =IF(G18>=0.997,0,IF(G18>=0.987,G17*0.01,IF(G18>=0.97,G17*0.03,IF(G18>=0.95,G17*0.05,IF(G18>=0.9,G17*0.1,G17*0.15))))) -> 0
A20: Call Centre Accessibility SLA (5.1.2) | C20: Accessibility @TCBH (should be > 95%) | G20: ='NOVEMBER 2025 IBD Data'!F380 -> 0.96390102 | H20: >=95% :0% , 90to<95% :5% , 85to<90% :10% , <85 :15%
C21: Penalty (Rs) Q | G21: =IF(G20>=0.95,0,IF(G20>=0.9,G17*0.05,IF(G20>=0.85,G17*0.1,G17*0.15))) -> 0
A22: Call Queue Waiting SLA (5.1.3) | C22: % Calls attended | D22: ='NOVEMBER 2025 IBD Data'!F384 -> 0.99576484 | E22: ='NOVEMBER 2025 IBD Data'!F385 -> 1 | F22: ='NOVEMBER 2025 IBD Data'!F386 -> 0.99025341 | H22: >=95% :0%, 85to<95% :5%, <85% :10%
C23: Penalty (Rs) R | D23: =IF(D22>=0.95,0,IF(D22>=0.85,D12*0.05,D12*0.1)) -> 0 | E23: =IF(E22>=0.95,0,IF(E22>=0.85,E12*0.05,E12*0.1)) -> 0 | F23: =IF(F22>=0.95,0,IF(F22>=0.85,F12*0.05,F12*0.1)) -> 0 | G23: =D23+E23+F23 -> 0
A24: Customer Satisfaction SLA (5.1.4) | C24: Average Satisfaction Score | G24: 2.25 | H24: >=2 :0% , 1.1to< 2 :3% , < 1.1 :5%
C25: Penalty (Rs) S | G25: =IF(G24>=2,0,IF(G24<1.1,G17*0.05,G17*0.03)) -> 0
A26: Call abandonment SLA (5.1.5) | C26: Calls unanswered by agents (should < 5%) | G26: ='NOVEMBER 2025 IBD Data'!F396 -> 0.01009078 | H26: <5% :0% , 5to10% :5% , >10% :10%
C27: Penalty (Rs) T | G27: =IF(G26<0.05,0,IF(G26>0.1,G17*0.1,G17*0.05)) -> 0
A28: Call quality SLA (5.1.6) | C28: Score on Call quality (should >85%) | G28: 86 | H28: >85 :0%, >80to85 :2%, 75to80 :5%, <75 :10%
C29: Penalty (Rs) U | G29: =IF(G28>85,0,IF(G28>80,G17*0.02,IF(G28>=75,G17*0.05,G17*0.1))) -> 0
A30: Penalty | C30: Total Penalty Amount Calculated (Rs) V | G30: =G19+G21+G23+G25+G27+G29 -> 0 | H30: V=P+Q+R+S+T+U
C31: % with respect to Total Bill amount W | G31: =G30/G17 -> 0 | H31: W=V/O
C32: 20% of Total Bill Amount (Rs) X | G32: =G17*0.2 -> 323853.94 | H32: X=O*0.2
A33: Total Amount excluding Penalties (Rs) Y | G33: =G17 -> 1619269.7

Sheet NOVEMBER 2025 IBD Data
A1: IVRS
A2: Max allowed daily average duration per call in Seconds | G2: 120
A3: Repeat Applicable
A4: 1. First Calls Day-wise
A5: CallDate | B5: Average Call Duaration (S) | C5: Call Count | D5: Total Duration (S) | E5: 120 * Call Count (S) | F5: Unit (S) | G5: Unit (Minutes)
A6: 45962 | B6: 54.6964 | C6: 6235 | D6: 341032.05 | E6: 748200 | F6: 341032.05 | G6: 5683.8676
A7: 45963 | B7: 54.2741 | C7: 5097 | D7: 276635.09 | E7: 611640 | F7: 276635.09 | G7: 4610.5848
A8: 45964 | B8: 55.3812 | C8: 5958 | D8: 329961.19 | E8: 714960 | F8: 329961.19 | G8: 5499.3532
A9: 45965 | B9: 55.4283 | C9: 6420 | D9: 355849.69 | E9: 770400 | F9: 355849.69 | G9: 5930.8281
A10: 45966 | B10: 54.8246 | C10: 5689 | D10: 311897.15 | E10: 682680 | F10: 311897.15 | G10: 5198.2858
A11: 45967 | B11: 52.678 | C11: 6466 | D11: 340615.95 | E11: 775920 | F11: 340615.95 | G11: 5676.9325
A12: 45968 | B12: 55.352 | C12: 6694 | D12: 370526.29 | E12: 803280 | F12: 370526.29 | G12: 6175.4381
A13: 45969 | B13: 54.0337 | C13: 5882 | D13: 317826.22 | E13: 705840 | F13: 317826.22 | G13: 5297.1037
A14: 45970 | B14: 53.7713 | C14: 5033 | D14: 270630.95 | E14: 603960 | F14: 270630.95 | G14: 4510.5159
A15: 45971 | B15: 52.6496 | C15: 6121 | D15: 322268.2 | E15: 734520 | F15: 322268.2 | G15: 5371.1367
A16: 45972 | B16: 56.3262 | C16: 5901 | D16: 332380.91 | E16: 708120 | F16: 332380.91 | G16: 5539.6818
A17: 45973 | B17: 54.8873 | C17: 5944 | D17: 326250.11 | E17: 713280 | F17: 326250.11 | G17: 5437.5019
... A35: 45991 | B35: 45.3048 | C35: 4400 | D35: 199341.12 | E35: 528000 | F35: 199341.12 | G35: 3322.352
C37: =SUBTOTAL(109,Table418[Call Count]) -> 178009 | D37: =SUBTOTAL(109,D6:D36) -> 9076149.1 | E37: =SUBTOTAL(109,E6:E36) -> 21361080 | F37: =SUBTOTAL(109,F6:F36) -> 9076149.1 | G37: =SUBTOTAL(109,Table418[Unit (Minutes)]) -> 151269.15
A39: 2. Repeated Calls Day-wise
A40: CallDate | B40: Average Call Duaration (S) | C40: Call Count | D40: Total Duration (S) | E40: 120 * Call Count (S) | F40: Unit (S) | G40: Unit (Minutes)
C72: =SUBTOTAL(109,Table519[Call Count]) -> 0 | D72: =SUBTOTAL(109,D41:D71) -> 0 | E72: =SUBTOTAL(109,E41:E71) -> 0 | F72: =SUBTOTAL(109,F41:F71) -> 0 | G72: =SUBTOTAL(109,Table519[Unit (Minutes)]) -> 0
A74: Repeat Not Applicable
A75: CallDate | B75: Average Call Duaration (S) | C75: Call Count | D75: Total Duration (S) | E75: 120 * Call Count (S) | F75: Unit (S) | G75: Unit (Minutes)
C107: =SUBTOTAL(109,Table620[Call Count]) -> 0 | D107: =SUBTOTAL(109,D76:D106) -> 0 | E107: =SUBTOTAL(109,E76:E106) -> 0 | F107: =SUBTOTAL(109,F76:F106) -> 0 | G107: =SUBTOTAL(109,Table620[Unit (Minutes)]) -> 0
A109: Agent - Segment 1
A110: Max allowed daily average duration per call in Seconds | G110: 130
A111: Repeat Applicable
A112: 1. First Calls Day-wise
A113: CallDate | B113: Average Call Duaration (S) | C113: Call Count | D113: Total Duration (S) | E113: 130 * Call Count (S) | F113: Unit (S) | G113: Unit (Minutes)
A114: 45962 | B114: 130.4459 | C114: 6484 | D114: 845811.22 | E114: 842920 | F114: 842920 | G114: 14048.667
A115: 45963 | B115: 131.3278 | C115: 5329 | D115: 699845.85 | E115: 692770 | F115: 692770 | G115: 11546.167
A116: 45964 | B116: 132.5796 | C116: 6397 | D116: 848111.7 | E116: 831610 | F116: 831610 | G116: 13860.167
A117: 45965 | B117: 140.8847 | C117: 6589 | D117: 928289.29 | E117: 856570 | F117: 856570 | G117: 14276.167
A118: 45966 | B118: 134.256 | C118: 6129 | D118: 822855.02 | E118: 796770 | F118: 796770 | G118: 13279.5
A119: 45967 | B119: 138.7142 | C119: 6273 | D119: 870154.18 | E119: 815490 | F119: 815490 | G119: 13591.5
A120: 45968 | B120: 136.1276 | C120: 6309 | D120: 858829.03 | E120: 820170 | F120: 820170 | G120: 13669.5
A121: 45969 | B121: 128.9329 | C121: 5914 | D121: 762509.17 | E121: 768820 | F121: 762509.17 | G121: 12708.486
A122: 45970 | B122: 133.8789 | C122: 5069 | D122: 678632.14 | E122: 658970 | F122: 658970 | G122: 10982.833
A123: 45971 | B123: 133.544 | C123: 6785 | D123: 906096.04 | E123: 882050 | F123: 882050 | G123: 14700.833
...

Sheet NOVEMBER 2025 OBD  Data
A1: OBD Call Centre CDR
A2: Segment 1
A3: Max allowed daily average duration per call in Seconds | G3: 130
A4: CallDate | B4: Average Call Duaration (S) | C4: Call Count | D4: Total Duration (S) | E4: 130 * Call Count (S) | F4: Unit (S) | G4: Unit (Minutes)
A5: 45962 | B5: 145.17647 | C5: 884 | D5: 128336 | E5: =Table7214[[#This Row],[Call Count]]*130 -> 114920 | F5: =IF(Table7214[[#This Row],[Total Duration (S)]]>Table7214[[#This Row],[130 * Call Count (S)]],Table7214[[#This Row],[130 * Call Count (S)]],Table7214[[#This Row],[Total Duration (S)]]) -> 114920 | G5: =Table7214[[#This Row],[Unit (S)]]/60 -> 1915.3333
A6: 45963 | B6: 157.5768 | C6: 1250 | D6: 196971 | E6: =Table7214[[#This Row],[Call Count]]*130 -> 162500 | F6: =IF(Table7214[[#This Row],[Total Duration (S)]]>Table7214[[#This Row],[130 * Call Count (S)]],Table7214[[#This Row],[130 * Call Count (S)]],Table7214[[#This Row],[Total Duration (S)]]) -> 162500 | G6: =Table7214[[#This Row],[Unit (S)]]/60 -> 2708.3333
A7: 45964 | B7: 156.98711 | C7: 776 | D7: 121822 | E7: =Table7214[[#This Row],[Call Count]]*130 -> 100880 | F7: =IF(Table7214[[#This Row],[Total Duration (S)]]>Table7214[[#This Row],[130 * Call Count (S)]],Table7214[[#This Row],[130 * Call Count (S)]],Table7214[[#This Row],[Total Duration (S)]]) -> 100880 | G7: =Table7214[[#This Row],[Unit (S)]]/60 -> 1681.3333
A8: 45965 | B8: 156.65899 | C8: 868 | D8: 135980 | E8: =Table7214[[#This Row],[Call Count]]*130 -> 112840 | F8: =IF(Table7214[[#This Row],[Total Duration (S)]]>Table7214[[#This Row],[130 * Call Count (S)]],Table7214[[#This Row],[130 * Call Count (S)]],Table7214[[#This Row],[Total Duration (S)]]) -> 112840 | G8: =Table7214[[#This Row],[Unit (S)]]/60 -> 1880.6667
A9: 45966 | B9: 153.57223 | C9: 1073 | D9: 164783 | E9: =Table7214[[#This Row],[Call Count]]*130 -> 139490 | F9: =IF(Table7214[[#This Row],[Total Duration (S)]]>Table7214[[#This Row],[130 * Call Count (S)]],Table7214[[#This Row],[130 * Call Count (S)]],Table7214[[#This Row],[Total Duration (S)]]) -> 139490 | G9: =Table7214[[#This Row],[Unit (S)]]/60 -> 2324.8333
A10: 45967 | B10: 157.61896 | C10: 1139 | D10: 179528 | E10: =Table7214[[#This Row],[Call Count]]*130 -> 148070 | F10: =IF(Table7214[[#This Row],[Total Duration (S)]]>Table7214[[#This Row],[130 * Call Count (S)]],Table7214[[#This Row],[130 * Call Count (S)]],Table7214[[#This Row],[Total Duration (S)]]) -> 148070 | G10: =Table7214[[#This Row],[Unit (S)]]/60 -> 2467.8333
A11: 45968 | B11: 152.24753 | C11: 1115 | D11: 169756 | E11: =Table7214[[#This Row],[Call Count]]*130 -> 144950 | F11: =IF(Table7214[[#This Row],[Total Duration (S)]]>Table7214[[#This Row],[130 * Call Count (S)]],Table7214[[#This Row],[130 * Call Count (S)]],Table7214[[#This Row],[Total Duration (S)]]) -> 144950 | G11: =Table7214[[#This Row],[Unit (S)]]/60 -> 2415.8333
A12: 45969 | B12: 149.11996 | C12: 917 | D12: 136743 | E12: =Table7214[[#This Row],[Call Count]]*130 -> 119210 | F12: =IF(Table7214[[#This Row],[Total Duration (S)]]>Table7214[[#This Row],[130 * Call Count (S)]],Table7214[[#This Row],[130 * Call Count (S)]],Table7214[[#This Row],[Total Duration (S)]]) -> 119210 | G12: =Table7214[[#This Row],[Unit (S)]]/60 -> 1986.8333
A13: 45970 | B13: 164.50974 | C13: 873 | D13: 143617 | E13: =Table7214[[#This Row],[Call Count]]*130 -> 113490 | F13: =IF(Table7214[[#This Row],[Total Duration (S)]]>Table7214[[#This Row],[130 * Call Count (S)]],Table7214[[#This Row],[130 * Call Count (S)]],Table7214[[#This Row],[Total Duration (S)]]) -> 113490 | G13: =Table7214[[#This Row],[Unit (S)]]/60 -> 1891.5
A14: 45971 | B14: 153.77477 | C14: 777 | D14: 119483 | E14: =Table7214[[#This Row],[Call Count]]*130 -> 101010 | F14: =IF(Table7214[[#This Row],[Total Duration (S)]]>Table7214[[#This Row],[130 * Call Count (S)]],Table7214[[#This Row],[130 * Call Count (S)]],Table7214[[#This Row],[Total Duration (S)]]) -> 101010 | G14: =Table7214[[#This Row],[Unit (S)]]/60 -> 1683.5
A15: 45972 | B15: 159.71272 | C15: 1093 | D15: 174566 | E15: =Table7214[[#This Row],[Call Count]]*130 -> 142090 | F15: =IF(Table7214[[#This Row],[Total Duration (S)]]>Table7214[[#This Row],[130 * Call Count (S)]],Table7214[[#This Row],[130 * Call Count (S)]],Table7214[[#This Row],[Total Duration (S)]]) -> 142090 | G15: =Table7214[[#This Row],[Unit (S)]]/60 -> 2368.1667
A16: 45973 | B16: 149.61855 | C16: 1046 | D16: 156501 | E16: =Table7214[[#This Row],[Call Count]]*130 -> 135980 | F16: =IF(Table7214[[#This Row],[Total Duration (S)]]>Table7214[[#This Row],[130 * Call Count (S)]],Table7214[[#This Row],[130 * Call Count (S)]],Table7214[[#This Row],[Total Duration (S)]]) -> 135980 | G16: =Table7214[[#This Row],[Unit (S)]]/60 -> 2266.3333
... A34: 45991 | B34: 154.12462 | C34: 650 | D34: 100181 | E34: =Table7214[[#This Row],[Call Count]]*130 -> 84500 | F34: =IF(Table7214[[#This Row],[Total Duration (S)]]>Table7214[[#This Row],[130 * Call Count (S)]],Table7214[[#This Row],[130 * Call Count (S)]],Table7214[[#This Row],[Total Duration (S)]]) -> 84500 | G34: =Table7214[[#This Row],[Unit (S)]]/60 -> 1408.3333
D36: =SUBTOTAL(109,Table7214[Total Duration (S)]) -> 4181298 | E36: =SUBTOTAL(109,E5:E35) -> 3497650 | F36: =SUBTOTAL(109,F5:F35) -> 3497650 | G36: =SUBTOTAL(109,Table7214[Unit (Minutes)]) -> 58294.167
A37: Segment 2
A38: Max allowed daily average duration per call in Seconds | G38: 150
A39: CallDate | B39: Average Call Duaration (S) | C39: Call Count | D39: Total Duration (S) | E39: 150 * Call Count (S) | F39: Unit (S) | G39: Unit (Minutes)
G71: =SUBTOTAL(109,Table9235[Unit (Minutes)]) -> 0
A73: Segment 3
A74: Max allowed daily average duration per call in Seconds | G74: 180
A75: CallDate | B75: Average Call Duaration (S) | C75: Call Count | D75: Total Duration (S) | E75: 180 * Call Count (S) | F75: Unit (S) | G75: Unit (Minutes)
G107: =SUBTOTAL(109,Table16296[Unit (Minutes)]) -> 0
